<?xml version="1.0" ?>

<!--           arm_tutorial.xacro            -->
<!-- This document describes the robot model -->
<!--       SubT Junior Tutorial Version      -->
<!--        Last editted: 29/05, 2019        -->
<!--            Editor: Wolf Chen            -->

<robot name="arm" xmlns:xacro="http://www.ros.org/wiki/xacro">

  <!-- BGN - Robot Description -->
  <link name="base_link">
    <visual>
      <origin rpy="0 0 0" xyz="0 0 0.1"/>
      <geometry>
        <cylinder radius="0.5" length="0.2"/>
      </geometry>
    </visual>
  </link>

  <joint name="base_joint" type="revolute">
    <axis xyz="0 1 0"/>
    <limit effort="1000.0" lower="-1.57" upper="1.57" velocity="0.2"/>
    <origin rpy="0 0 0" xyz="0 0 0.1"/>
    <parent link="base_link"/>
    <child link="shoulder_link"/>
  </joint>

  <link name="shoulder_link">
    <visual>
      <origin rpy="0 0 0" xyz="0 0 0.5"/>
      <geometry>
        <box size="0.2 0.5 1"/>
      </geometry>
    </visual>
  </link>
</robot>
