<?xml version="1.0" ?>

<!--              links_joints.xacro              -->
<!-- This document describes the global functions -->
<!--      Machenical Practice Testing Version     -->
<!--           Last editted: 11/18, 2018          -->
<!--               Editor: Wolf Chen              -->

<robot xmlns:xacro="http://www.ros.org/wiki/xacro">

  <!-- Define the "joint" description -->
  <xacro:macro name="arm_joint_s" params="name type axis_xyz limit origin_rpy origin_xyz parent child">
    <joint name="${name}" type="${type}">
      <axis xyz="${axis_xyz}"/>
      <limit effort="1000.0" lower="-${limit}" upper="${limit}" velocity="0.2"/>
      <!-- Define the origin of the NEXT link -->
      <origin rpy="${origin_rpy}" xyz="${origin_xyz}"/>
      <parent link="${parent}"/>
      <child link="${child}"/>
    </joint>
  </xacro:macro>

  <xacro:macro name="arm_joint_dl_s" params="name type axis_xyz lower upper origin_rpy origin_xyz parent child">
    <joint name="${name}" type="${type}">
      <axis xyz="${axis_xyz}"/>
      <limit effort="1000.0" lower="-${lower}" upper="${upper}" velocity="0.2"/>
      <!-- Define the origin of the NEXT link -->
      <origin rpy="${origin_rpy}" xyz="${origin_xyz}"/>
      <parent link="${parent}"/>
      <child link="${child}"/>
    </joint>
  </xacro:macro>

  <xacro:macro name="arm_joint_con_s" params="name axis_xyz origin_rpy origin_xyz parent child">
    <joint name="${name}" type="continuous">
      <axis xyz="${axis_xyz}"/>
      <limit effort="1000.0" velocity="0.2"/>
      <!-- Define the origin of the NEXT link -->
      <origin rpy="${origin_rpy}" xyz="${origin_xyz}"/>
      <parent link="${parent}"/>
      <child link="${child}"/>
    </joint>
  </xacro:macro>

  <xacro:macro name="arm_joint" params="name type axis_xyz limit origin_rpy origin_xyz parent child">
    <joint name="${name}" type="${type}">
      <axis xyz="${axis_xyz}"/>
      <limit effort="1000.0" lower="-${limit}" upper="${limit}" velocity="0.2"/>
      <!-- Define the origin of the NEXT link -->
      <origin rpy="${origin_rpy}" xyz="${origin_xyz}"/>
      <parent link="${parent}"/>
      <child link="${child}"/>
    </joint>
    <transmission name="trans_${name}">
      <type>transmission_interface/SimpleTransmission</type>
      <joint name="${name}">
        <hardwareInterface>hardware_interface/EffortJointInterface</hardwareInterface>
      </joint>
      <actuator name="motor_${name}">
        <hardwareInterface>hardware_interface/EffortJointInterface</hardwareInterface>
        <mechanicalReduction>1</mechanicalReduction>
      </actuator>
    </transmission>
  </xacro:macro>

  <xacro:macro name="arm_joint_dl" params="name type axis_xyz lower upper origin_rpy origin_xyz parent child">
    <joint name="${name}" type="${type}">
      <axis xyz="${axis_xyz}"/>
      <limit effort="1000.0" lower="-${lower}" upper="${upper}" velocity="0.2"/>
      <!-- Define the origin of the NEXT link -->
      <origin rpy="${origin_rpy}" xyz="${origin_xyz}"/>
      <parent link="${parent}"/>
      <child link="${child}"/>
    </joint>
    <transmission name="trans_${name}">
      <type>transmission_interface/SimpleTransmission</type>
      <joint name="${name}">
        <hardwareInterface>hardware_interface/EffortJointInterface</hardwareInterface>
      </joint>
      <actuator name="motor_${name}">
        <hardwareInterface>hardware_interface/EffortJointInterface</hardwareInterface>
        <mechanicalReduction>1</mechanicalReduction>
      </actuator>
    </transmission>
  </xacro:macro>

  <xacro:macro name="arm_joint_con" params="name axis_xyz origin_rpy origin_xyz parent child">
    <joint name="${name}" type="continuous">
      <axis xyz="${axis_xyz}"/>
      <limit effort="1000.0" velocity="0.2"/>
      <!-- Define the origin of the NEXT link -->
      <origin rpy="${origin_rpy}" xyz="${origin_xyz}"/>
      <parent link="${parent}"/>
      <child link="${child}"/>
    </joint>
    <transmission name="trans_${name}">
      <type>transmission_interface/SimpleTransmission</type>
      <joint name="${name}">
        <hardwareInterface>hardware_interface/EffortJointInterface</hardwareInterface>
      </joint>
      <actuator name="motor_${name}">
        <hardwareInterface>hardware_interface/EffortJointInterface</hardwareInterface>
        <mechanicalReduction>1</mechanicalReduction>
      </actuator>
    </transmission>
  </xacro:macro>

  <!-- Define the "arm body" description -->
  <xacro:macro name="arm_cylinder" params="name mass origin_rpy origin_xyz ixx ixy ixz iyy iyz izz radius length color_name color">
    <link name="${name}">
      <inertial>
        <mass value="${mass}"/>
        <origin rpy="${origin_rpy}" xyz="${origin_xyz}"/>
        <inertia ixx="${ixx}" ixy="${ixy}" ixz="${ixz}" iyy="${iyy}" iyz="${iyz}" izz="${izz}"/>
      </inertial>
      <collision>
        <origin rpy="${origin_rpy}" xyz="${origin_xyz}"/>
        <geometry>
          <cylinder radius="${radius}" length="${length}"/>
        </geometry>
      </collision>
      <visual>
        <origin rpy="${origin_rpy}" xyz="${origin_xyz}"/>
        <geometry>
          <cylinder radius="${radius}" length="${length}"/>
          <material name="${color_name}">
            <color rgba="${color}"/>
          </material>
        </geometry>
      </visual>
    </link>
  </xacro:macro>

  <xacro:macro name="arm_box" params="name mass origin_rpy origin_xyz ixx ixy ixz iyy iyz izz size color_name color">
    <link name="${name}">
      <inertial>
        <mass value="${mass}"/>
        <origin rpy="${origin_rpy}" xyz="${origin_xyz}"/>
        <inertia ixx="${ixx}" ixy="${ixy}" ixz="${ixz}" iyy="${iyy}" iyz="${iyz}" izz="${izz}"/>
      </inertial>
      <collision>
        <origin rpy="${origin_rpy}" xyz="${origin_xyz}"/>
        <geometry>
          <box size="${size}"/>
        </geometry>
      </collision>
      <visual>
        <origin rpy="${origin_rpy}" xyz="${origin_xyz}"/>
        <geometry>
          <box size="${size}"/>
          <material name="${color_name}">
            <color rgba="${color}"/>
          </material>
        </geometry>
      </visual>
    </link>
  </xacro:macro>

  <!-- Define the "transmission" description -->
  <xacro:macro name="arm_trans" params="name">
    <transmission name="trans_${name}">
      <type>transmission_interface/SimpleTransmission</type>
      <joint name="${name}">
        <hardwareInterface>hardware_interface/EffortJointInterface</hardwareInterface>
      </joint>
      <actuator name="motor_${name}">
        <hardwareInterface>hardware_interface/EffortJointInterface</hardwareInterface>
        <mechanicalReduction>1</mechanicalReduction>
      </actuator>
    </transmission>
  </xacro:macro>

</robot>
